[2024-04-09 21:36:33,730] {taskinstance.py:1179} INFO - Dependencies all met for <TaskInstance: NEO_coderhouse.Cargar_datos_redshift manual__2024-04-09T21:36:27.090664+00:00 [queued]>
[2024-04-09 21:36:33,740] {taskinstance.py:1179} INFO - Dependencies all met for <TaskInstance: NEO_coderhouse.Cargar_datos_redshift manual__2024-04-09T21:36:27.090664+00:00 [queued]>
[2024-04-09 21:36:33,741] {taskinstance.py:1376} INFO - 
--------------------------------------------------------------------------------
[2024-04-09 21:36:33,742] {taskinstance.py:1377} INFO - Starting attempt 1 of 6
[2024-04-09 21:36:33,743] {taskinstance.py:1378} INFO - 
--------------------------------------------------------------------------------
[2024-04-09 21:36:33,757] {taskinstance.py:1397} INFO - Executing <Task(PythonOperator): Cargar_datos_redshift> on 2024-04-09 21:36:27.090664+00:00
[2024-04-09 21:36:33,761] {standard_task_runner.py:52} INFO - Started process 484 to run task
[2024-04-09 21:36:33,764] {standard_task_runner.py:79} INFO - Running: ['***', 'tasks', 'run', 'NEO_coderhouse', 'Cargar_datos_redshift', 'manual__2024-04-09T21:36:27.090664+00:00', '--job-id', '136', '--raw', '--subdir', 'DAGS_FOLDER/dag.py', '--cfg-path', '/tmp/tmpga1pxk57', '--error-file', '/tmp/tmp2fin1ums']
[2024-04-09 21:36:33,766] {standard_task_runner.py:80} INFO - Job 136: Subtask Cargar_datos_redshift
[2024-04-09 21:36:33,827] {task_command.py:371} INFO - Running <TaskInstance: NEO_coderhouse.Cargar_datos_redshift manual__2024-04-09T21:36:27.090664+00:00 [running]> on host c346f321fefe
[2024-04-09 21:36:33,888] {taskinstance.py:1591} INFO - Exporting the following env vars:
AIRFLOW_CTX_DAG_OWNER=LukeFo
AIRFLOW_CTX_DAG_ID=NEO_coderhouse
AIRFLOW_CTX_TASK_ID=Cargar_datos_redshift
AIRFLOW_CTX_EXECUTION_DATE=2024-04-09T21:36:27.090664+00:00
AIRFLOW_CTX_TRY_NUMBER=1
AIRFLOW_CTX_DAG_RUN_ID=manual__2024-04-09T21:36:27.090664+00:00
[2024-04-09 21:36:33,889] {logging_mixin.py:115} INFO - Hola
[2024-04-09 21:36:34,817] {taskinstance.py:1909} ERROR - Task failed with exception
Traceback (most recent call last):
  File "/home/airflow/.local/lib/python3.7/site-packages/airflow/operators/python.py", line 171, in execute
    return_value = self.execute_callable()
  File "/home/airflow/.local/lib/python3.7/site-packages/airflow/operators/python.py", line 189, in execute_callable
    return self.python_callable(*self.op_args, **self.op_kwargs)
  File "/opt/airflow/dags/dag.py", line 100, in cargar_redshift
    neo = pd.DataFrame(neo_json)
  File "/home/airflow/.local/lib/python3.7/site-packages/pandas/core/frame.py", line 730, in __init__
    raise ValueError("DataFrame constructor not properly called!")
ValueError: DataFrame constructor not properly called!
[2024-04-09 21:36:34,832] {taskinstance.py:1420} INFO - Marking task as UP_FOR_RETRY. dag_id=NEO_coderhouse, task_id=Cargar_datos_redshift, execution_date=20240409T213627, start_date=20240409T213633, end_date=20240409T213634
[2024-04-09 21:36:34,847] {standard_task_runner.py:97} ERROR - Failed to execute job 136 for task Cargar_datos_redshift (DataFrame constructor not properly called!; 484)
[2024-04-09 21:36:34,864] {local_task_job.py:156} INFO - Task exited with return code 1
[2024-04-09 21:36:34,895] {local_task_job.py:273} INFO - 0 downstream tasks scheduled from follow-on schedule check
