[2024-04-09 21:35:53,195] {taskinstance.py:1179} INFO - Dependencies all met for <TaskInstance: NEO_coderhouse.Cargar_datos_redshift manual__2024-04-09T21:35:47.207122+00:00 [queued]>
[2024-04-09 21:35:53,207] {taskinstance.py:1179} INFO - Dependencies all met for <TaskInstance: NEO_coderhouse.Cargar_datos_redshift manual__2024-04-09T21:35:47.207122+00:00 [queued]>
[2024-04-09 21:35:53,208] {taskinstance.py:1376} INFO - 
--------------------------------------------------------------------------------
[2024-04-09 21:35:53,209] {taskinstance.py:1377} INFO - Starting attempt 1 of 6
[2024-04-09 21:35:53,209] {taskinstance.py:1378} INFO - 
--------------------------------------------------------------------------------
[2024-04-09 21:35:53,226] {taskinstance.py:1397} INFO - Executing <Task(PythonOperator): Cargar_datos_redshift> on 2024-04-09 21:35:47.207122+00:00
[2024-04-09 21:35:53,231] {standard_task_runner.py:52} INFO - Started process 433 to run task
[2024-04-09 21:35:53,234] {standard_task_runner.py:79} INFO - Running: ['***', 'tasks', 'run', 'NEO_coderhouse', 'Cargar_datos_redshift', 'manual__2024-04-09T21:35:47.207122+00:00', '--job-id', '129', '--raw', '--subdir', 'DAGS_FOLDER/dag.py', '--cfg-path', '/tmp/tmph72uv7m0', '--error-file', '/tmp/tmpwlsg0d66']
[2024-04-09 21:35:53,235] {standard_task_runner.py:80} INFO - Job 129: Subtask Cargar_datos_redshift
[2024-04-09 21:35:53,295] {task_command.py:371} INFO - Running <TaskInstance: NEO_coderhouse.Cargar_datos_redshift manual__2024-04-09T21:35:47.207122+00:00 [running]> on host c346f321fefe
[2024-04-09 21:35:53,354] {taskinstance.py:1591} INFO - Exporting the following env vars:
AIRFLOW_CTX_DAG_OWNER=LukeFo
AIRFLOW_CTX_DAG_ID=NEO_coderhouse
AIRFLOW_CTX_TASK_ID=Cargar_datos_redshift
AIRFLOW_CTX_EXECUTION_DATE=2024-04-09T21:35:47.207122+00:00
AIRFLOW_CTX_TRY_NUMBER=1
AIRFLOW_CTX_DAG_RUN_ID=manual__2024-04-09T21:35:47.207122+00:00
[2024-04-09 21:35:53,356] {logging_mixin.py:115} INFO - Hola
[2024-04-09 21:35:54,440] {taskinstance.py:1909} ERROR - Task failed with exception
Traceback (most recent call last):
  File "/home/airflow/.local/lib/python3.7/site-packages/airflow/operators/python.py", line 171, in execute
    return_value = self.execute_callable()
  File "/home/airflow/.local/lib/python3.7/site-packages/airflow/operators/python.py", line 189, in execute_callable
    return self.python_callable(*self.op_args, **self.op_kwargs)
  File "/opt/airflow/dags/dag.py", line 100, in cargar_redshift
    neo = pd.DataFrame(neo)
  File "/home/airflow/.local/lib/python3.7/site-packages/pandas/core/frame.py", line 730, in __init__
    raise ValueError("DataFrame constructor not properly called!")
ValueError: DataFrame constructor not properly called!
[2024-04-09 21:35:54,459] {taskinstance.py:1420} INFO - Marking task as UP_FOR_RETRY. dag_id=NEO_coderhouse, task_id=Cargar_datos_redshift, execution_date=20240409T213547, start_date=20240409T213553, end_date=20240409T213554
[2024-04-09 21:35:54,470] {standard_task_runner.py:97} ERROR - Failed to execute job 129 for task Cargar_datos_redshift (DataFrame constructor not properly called!; 433)
[2024-04-09 21:35:54,493] {local_task_job.py:156} INFO - Task exited with return code 1
[2024-04-09 21:35:54,548] {local_task_job.py:273} INFO - 0 downstream tasks scheduled from follow-on schedule check
